Workbook

Sheet Leyenda
A1: DealCommerce · Diccionario de datos
A2: Versión 1 · 04-10-2026 · Pedro Santibáñez y Daniel Azócar · PostgreSQL 17 con Django
A4: Hojas
A5: Índice | B5: Una fila por tabla: grupo, estado, descripción y cantidad de campos.
A6: Diccionario | B6: Una fila por campo de cada tabla. Usa los filtros del encabezado para ver una tabla o un estado.
A7: Restricciones | B7: Reglas de unicidad y de validación que no caben en un solo campo.
A9: Estado de cada tabla
A10: Implementado | B10: Existe en el código (backend/apps).
A11: Planificado | B11: Diseñado, todavía sin programar. Puede cambiar al implementarse.
A12: Decisión pendiente | B12: Existe en el código, pero se decide con el cliente si se mantiene.
A13: Congelado | B13: Existe en el código, pero no se avanza hasta que el cliente lo confirme.
A15: Columna Clave
A16: PK | B16: Clave primaria.
A17: FK | B17: Clave foránea. La columna Referencia indica la tabla y qué pasa al borrar (CASCADE, PROTECT, SET NULL).
A18: UQ | B18: Valor único (solo o combinado con la tienda; ver Restricciones).
A20: Reglas generales
A21: Aislamiento | B21: Toda tabla con tienda_id pertenece a una tienda. Toda consulta se filtra por la tienda del usuario autenticado; pedir un dato de otra tienda responde 404.
A22: Montos | B22: Pesos chilenos enteros, netos (sin IVA). El IVA (19%) se calcula aparte con Decimal y redondeo medio hacia arriba.
A23: Gramos | B23: Decimal, nunca Float.
A24: Fechas | B24: Se guardan en UTC y se muestran en hora de Chile (America/Santiago).
A25: Archivos | B25: Las imágenes y planillas viven en Cloudflare R2; la base guarda solo la clave del objeto.
A26: Base común | B26: Las tablas con tienda heredan tienda_id, fecha_creacion y fecha_edicion del modelo base ModeloDeTienda.
A27: Django | B27: La tabla usuario además usa las tablas de grupos y permisos propias de Django, que no se detallan aquí.

Sheet Índice
A1: N° | B1: Tabla | C1: Modelo Django | D1: Grupo | E1: Estado | F1: Campos | G1: Descripción
A2: 1 | B2: tienda | C2: Tienda | D2: Identidad y acceso | E2: Implementado | F2: =COUNTIF(Diccionario!$A$2:$A$220,B2) -> 13 | G2: Cada comercio suscrito a la plataforma. Es la raíz del aislamiento: todo dato cuelga de una tienda.
A3: 2 | B3: usuario | C3: Usuario | D3: Identidad y acceso | E3: Implementado | F3: =COUNTIF(Diccionario!$A$2:$A$220,B3) -> 12 | G3: Cuentas de acceso. El rol define qué puede hacer; la tienda define qué datos puede ver.
A4: 3 | B4: solicitud_de_acceso | C4: SolicitudDeAcceso | D4: Identidad y acceso | E4: Implementado | F4: =COUNTIF(Diccionario!$A$2:$A$220,B4) -> 9 | G4: Negocios que pidieron entrar a la plataforma desde la portada. Única tabla sin tienda: existe antes de que la tienda exista.
A5: 4 | B5: aprobacion_mayorista | C5: AprobacionMayorista | D5: Identidad y acceso | E5: Decisión pendiente | F5: =COUNTIF(Diccionario!$A$2:$A$220,B5) -> 8 | G5: Estado de un comprador en una tienda. Pendiente de decidir si se mantiene, se adapta o se elimina, según si el cliente aprueba compradores.
A6: 5 | B6: categoria | C6: Categoria | D6: Catálogo y precios | E6: Planificado | F6: =COUNTIF(Diccionario!$A$2:$A$220,B6) -> 5 | G6: Categorías de pieza de cada tienda. Las usan la composición de los lotes y el pronóstico.
A7: 6 | B7: lote | C7: Lote | D7: Catálogo y precios | E7: Planificado | F7: =COUNTIF(Diccionario!$A$2:$A$220,B7) -> 14 | G7: Unidad de venta cerrada. Es una composición (piezas por categoría), no una lista de piezas concretas.
A8: 7 | B8: composicion_lote | C8: ComposicionLote | D8: Catálogo y precios | E8: Planificado | F8: =COUNTIF(Diccionario!$A$2:$A$220,B8) -> 7 | G8: Cuántas piezas de cada categoría trae un lote.
A9: 8 | B9: linea_granel | C9: LineaGranel | D9: Catálogo y precios | E9: Planificado | F9: =COUNTIF(Diccionario!$A$2:$A$220,B9) -> 10 | G9: Venta por gramo. No tiene stock: el dueño la activa o desactiva a mano.
A10: 9 | B10: tramo_precio | C10: TramoPrecio | D10: Catálogo y precios | E10: Planificado | F10: =COUNTIF(Diccionario!$A$2:$A$220,B10) -> 8 | G10: Tramos de precio por cantidad, para una línea de granel o para los lotes de la tienda.
A11: 10 | B11: pedido | C11: Pedido | D11: Pedidos | E11: Planificado | F11: =COUNTIF(Diccionario!$A$2:$A$220,B11) -> 12 | G11: Pedido de un comprador. Checkout simulado: no se cobra; el pago se coordina por WhatsApp.
A12: 11 | B12: linea_pedido | C12: LineaPedido | D12: Pedidos | E12: Planificado | F12: =COUNTIF(Diccionario!$A$2:$A$220,B12) -> 10 | G12: Cada lote o cantidad de gramos dentro de un pedido.
A13: 12 | B13: carga | C13: Carga | D13: Carga masiva | E13: Planificado | F13: =COUNTIF(Diccionario!$A$2:$A$220,B13) -> 12 | G13: Registro de cada planilla o .zip subido. Sirve para auditar de dónde salió cada dato del catálogo.
... A22: 21 | B22: envio_correo | C22: EnvioCorreo | D22: Agenda de visitas | E22: Congelado | F22: =COUNTIF(Diccionario!$A$2:$A$220,B22) -> 11 | G22: Correos de la agenda. Un fallo de envío no pierde la visita: se reintenta.
E23: Total campos | F23: =SUM(F2:F22) -> 219
D25: Tablas por estado | E25: Implementado | F25: =COUNTIF(E2:E22,E25) -> 3
E26: Planificado | F26: =COUNTIF(E2:E22,E26) -> 12
E27: Decisión pendiente | F27: =COUNTIF(E2:E22,E27) -> 1
E28: Congelado | F28: =COUNTIF(E2:E22,E28) -> 5

Sheet Diccionario
A1: Tabla | B1: Modelo Django | C1: Grupo | D1: Estado | E1: N° | F1: Campo | G1: Tipo PostgreSQL | H1: Tipo Django | I1: Nulo | J1: Clave | K1: Referencia · al borrar | L1: Valor por defecto | M1: Reglas y valores permitidos | N1: Descripción
A2: tienda | B2: Tienda | C2: Identidad y acceso | D2: Implementado | E2: 1 | F2: id | G2: bigint | H2: BigAutoField | I2: No | J2: PK | L2: Autoincremental | N2: Identificador interno.
A3: tienda | B3: Tienda | C3: Identidad y acceso | D3: Implementado | E3: 2 | F3: slug | G3: varchar(60) | H3: SlugField | I3: No | J3: UQ | M3: Único. Solo minúsculas, números y guiones. | N3: Identificador público; va en la ruta /t/<slug>/.
A4: tienda | B4: Tienda | C4: Identidad y acceso | D4: Implementado | E4: 3 | F4: nombre | G4: varchar(120) | H4: CharField | I4: No | N4: Nombre comercial de la tienda.
A5: tienda | B5: Tienda | C5: Identidad y acceso | D5: Implementado | E5: 4 | F5: activa | G5: boolean | H5: BooleanField | I5: No | L5: true | N5: Una tienda inactiva no se muestra al público.
A6: tienda | B6: Tienda | C6: Identidad y acceso | D6: Implementado | E6: 5 | F6: logo | G6: varchar(100) | H6: ImageField | I6: Sí | M6: Archivo en Cloudflare R2; se guarda solo la clave. | N6: Logo de la tienda.
A7: tienda | B7: Tienda | C7: Identidad y acceso | D7: Implementado | E7: 6 | F7: banner | G7: varchar(100) | H7: ImageField | I7: Sí | M7: Archivo en Cloudflare R2; se guarda solo la clave. | N7: Imagen de portada de la tienda.
A8: tienda | B8: Tienda | C8: Identidad y acceso | D8: Implementado | E8: 7 | F8: color_primario | G8: varchar(7) | H8: CharField | I8: Sí (vacío) | M8: Formato hexadecimal #RRGGBB, validado. Nunca CSS libre. | N8: Color principal de la tienda.
A9: tienda | B9: Tienda | C9: Identidad y acceso | D9: Implementado | E9: 8 | F9: color_primario_hover | G9: varchar(7) | H9: CharField | I9: Sí (vacío) | M9: Formato hexadecimal #RRGGBB, validado. | N9: Color principal al pasar el mouse.
A10: tienda | B10: Tienda | C10: Identidad y acceso | D10: Implementado | E10: 9 | F10: color_acento | G10: varchar(7) | H10: CharField | I10: Sí (vacío) | M10: Formato hexadecimal #RRGGBB, validado. | N10: Color de acento.
A11: tienda | B11: Tienda | C11: Identidad y acceso | D11: Implementado | E11: 10 | F11: color_destacado | G11: varchar(7) | H11: CharField | I11: Sí (vacío) | M11: Formato hexadecimal #RRGGBB, validado. | N11: Color para destacados.
A12: tienda | B12: Tienda | C12: Identidad y acceso | D12: Implementado | E12: 11 | F12: whatsapp | G12: varchar(200) | H12: URLField | I12: Sí (vacío) | M12: URL válida. | N12: Enlace de WhatsApp de la tienda.
A13: tienda | B13: Tienda | C13: Identidad y acceso | D13: Implementado | E13: 12 | F13: instagram | G13: varchar(200) | H13: URLField | I13: Sí (vacío) | M13: URL válida. | N13: Enlace de Instagram de la tienda.
A14: tienda | B14: Tienda | C14: Identidad y acceso | D14: Implementado | E14: 13 | F14: fecha_creacion | G14: timestamp with time zone | H14: DateTimeField(auto_now_add) | I14: No | L14: Ahora | N14: Fecha de alta de la tienda.
A15: usuario | B15: Usuario | C15: Identidad y acceso | D15: Implementado | E15: 1 | F15: id | G15: bigint | H15: BigAutoField | I15: No | J15: PK | L15: Autoincremental | N15: Identificador interno.
A16: usuario | B16: Usuario | C16: Identidad y acceso | D16: Implementado | E16: 2 | F16: email | G16: varchar(254) | H16: EmailField | I16: No | J16: UQ | M16: Se guarda en minúsculas. Es el nombre de usuario. | N16: Correo de la cuenta.
A17: usuario | B17: Usuario | C17: Identidad y acceso | D17: Implementado | E17: 3 | F17: password | G17: varchar(128) | H17: CharField (Django) | I17: No | M17: Hash; nunca la contraseña en texto plano. | N17: Contraseña cifrada.
A18: usuario | B18: Usuario | C18: Identidad y acceso | D18: Implementado | E18: 4 | F18: nombre | G18: varchar(150) | H18: CharField | I18: No | N18: Nombre de la persona.
A19: usuario | B19: Usuario | C19: Identidad y acceso | D19: Implementado | E19: 5 | F19: rut | G19: varchar(12) | H19: CharField | I19: Sí | J19: UQ | M19: Formato 12345678-5, sin puntos; dígito verificador validado. | N19: RUT chileno, opcional.
A20: usuario | B20: Usuario | C20: Identidad y acceso | D20: Implementado | E20: 6 | F20: rol | G20: varchar(20) | H20: CharField(choices) | I20: No | M20: admin_plataforma | dueno_tienda | vendedor | comprador | N20: Rol de la cuenta.
A21: usuario | B21: Usuario | C21: Identidad y acceso | D21: Implementado | E21: 7 | F21: tienda_id | G21: bigint | H21: ForeignKey(Tienda) | I21: Sí | J21: FK | K21: tienda.id · PROTECT | M21: CHECK: obligatorio para dueno_tienda y vendedor; nulo para admin_plataforma y comprador. | N21: Tienda donde trabaja la persona.
A22: usuario | B22: Usuario | C22: Identidad y acceso | D22: Implementado | E22: 8 | F22: is_active | G22: boolean | H22: BooleanField | I22: No | L22: true | N22: Cuenta habilitada.
A23: usuario | B23: Usuario | C23: Identidad y acceso | D23: Implementado | E23: 9 | F23: is_staff | G23: boolean | H23: BooleanField | I23: No | L23: false | N23: Puede entrar al panel de administración de Django.
A24: usuario | B24: Usuario | C24: Identidad y acceso | D24: Implementado | E24: 10 | F24: is_superuser | G24: boolean | H24: BooleanField (Django) | I24: No | L24: false | N24: Tiene todos los permisos de Django.
A25: usuario | B25: Usuario | C25: Identidad y acceso | D25: Implementado | E25: 11 | F25: last_login | G25: timestamp with time zone | H25: DateTimeField (Django) | I25: Sí | N25: Último inicio de sesión.
A26: usuario | B26: Usuario | C26: Identidad y acceso | D26: Implementado | E26: 12 | F26: fecha_registro | G26: timestamp with time zone | H26: DateTimeField(auto_now_add) | I26: No | L26: Ahora | N26: Fecha de creación de la cuenta.
A27: solicitud_de_acceso | B27: SolicitudDeAcceso | C27: Identidad y acceso | D27: Implementado | E27: 1 | F27: id | G27: bigint | H27: BigAutoField | I27: No | J27: PK | L27: Autoincremental | N27: Identificador interno.
A28: solicitud_de_acceso | B28: SolicitudDeAcceso | C28: Identidad y acceso | D28: Implementado | E28: 2 | F28: negocio | G28: varchar(150) | H28: CharField | I28: No | N28: Nombre del negocio.
A29: solicitud_de_acceso | B29: SolicitudDeAcceso | C29: Identidad y acceso | D29: Implementado | E29: 3 | F29: nombre | G29: varchar(150) | H29: CharField | I29: No | N29: Nombre de contacto.
A30: solicitud_de_acceso | B30: SolicitudDeAcceso | C30: Identidad y acceso | D30: Implementado | E30: 4 | F30: email | G30: varchar(254) | H30: EmailField | I30: No | J30: UQ | M30: Se guarda en minúsculas. | N30: Correo de contacto.
A31: solicitud_de_acceso | B31: SolicitudDeAcceso | C31: Identidad y acceso | D31: Implementado | E31: 5 | F31: telefono | G31: varchar(30) | H31: CharField | I31: No | N31: Teléfono o WhatsApp.
A32: solicitud_de_acceso | B32: SolicitudDeAcceso | C32: Identidad y acceso | D32: Implementado | E32: 6 | F32: mensaje | G32: text | H32: TextField | I32: Sí (vacío) | N32: Qué vende el negocio.
A33: solicitud_de_acceso | B33: SolicitudDeAcceso | C33: Identidad y acceso | D33: Implementado | E33: 7 | F33: estado | G33: varchar(20) | H33: CharField(choices) | I33: No | L33: nueva | M33: nueva | contactada | activada | descartada | N33: Seguimiento de la solicitud.
A34: solicitud_de_acceso | B34: SolicitudDeAcceso | C34: Identidad y acceso | D34: Implementado | E34: 8 | F34: notas | G34: text | H34: TextField | I34: Sí (vacío) | M34: Uso interno. | N34: Notas del administrador de la plataforma.
A35: solicitud_de_acceso | B35: SolicitudDeAcceso | C35: Identidad y acceso | D35: Implementado | E35: 9 | F35: fecha_creacion | G35: timestamp with time zone | H35: DateTimeField(auto_now_add) | I35: No | L35: Ahora | N35: Fecha de la solicitud.
A36: aprobacion_mayorista | B36: AprobacionMayorista | C36: Identidad y acceso | D36: Decisión pendiente | E36: 1 | F36: id | G36: bigint | H36: BigAutoField | I36: No | J36: PK | L36: Autoincremental | N36: Identificador interno.
A37: aprobacion_mayorista | B37: AprobacionMayorista | C37: Identidad y acceso | D37: Decisión pendiente | E37: 2 | F37: tienda_id | G37: bigint | H37: ForeignKey(Tienda) | I37: No | J37: FK | K37: tienda.id · CASCADE | M37: Se toma del token del usuario, nunca del cuerpo de la petición. | N37: Tienda a la que pertenece la fila. Raíz del aislamiento entre tiendas.
A38: aprobacion_mayorista | B38: AprobacionMayorista | C38: Identidad y acceso | D38: Decisión pendiente | E38: 3 | F38: comprador_id | G38: bigint | H38: ForeignKey(Usuario) | I38: No | J38: FK | K38: usuario.id · CASCADE | M38: Debe ser un usuario con rol comprador. | N38: Comprador evaluado.
A39: aprobacion_mayorista | B39: AprobacionMayorista | C39: Identidad y acceso | D39: Decisión pendiente | E39: 4 | F39: estado | G39: varchar(20) | H39: CharField(choices) | I39: No | L39: sin_solicitar | M39: sin_solicitar | pendiente | aprobado | rechazado | N39: Estado de la aprobación.
A40: aprobacion_mayorista | B40: AprobacionMayorista | C40: Identidad y acceso | D40: Decisión pendiente | E40: 5 | F40: fecha_resolucion | G40: timestamp with time zone | H40: DateTimeField | I40: Sí | N40: Cuándo se aprobó o rechazó.
...

Sheet Restricciones
A1: Tabla | B1: Tipo | C1: Definición | D1: Para qué sirve | E1: Estado
A2: usuario | B2: CHECK | C2: rol ∈ (dueno_tienda, vendedor) ⇒ tienda_id no nulo; rol ∈ (admin_plataforma, comprador) ⇒ tienda_id nulo | D2: Que nadie trabaje en una tienda sin pertenecer a ella, ni un comprador quede atado a una. | E2: Implementado
A3: aprobacion_mayorista | B3: UNIQUE | C3: (tienda_id, comprador_id) | D3: Un estado por comprador en cada tienda. | E3: Decisión pendiente
A4: categoria | B4: UNIQUE | C4: (tienda_id, nombre) | D4: Sin categorías repetidas en una tienda. | E4: Planificado
A5: lote | B5: UNIQUE | C5: (tienda_id, codigo) | D5: Que la carga masiva actualice en vez de duplicar. | E5: Planificado
A6: lote | B6: CHECK | C6: 0 ≤ cupos_disponibles ≤ cupos_totales | D6: Nunca vender más cupos de los que existen. | E6: Planificado
A7: lote | B7: CHECK | C7: tipo_cupo = UNICO ⇒ cupos_totales = 1 | D7: Un cupo único se vende una sola vez. | E7: Planificado
A8: lote | B8: VALIDACIÓN | C8: cantidad_piezas = suma de composicion_lote.cantidad | D8: La composición cuadra con el total de piezas (se valida al guardar). | E8: Planificado
A9: composicion_lote | B9: UNIQUE | C9: (lote_id, categoria_id) | D9: Una fila por categoría en cada lote. | E9: Planificado
A10: linea_granel | B10: UNIQUE | C10: (tienda_id, codigo) | D10: Que la carga masiva actualice en vez de duplicar. | E10: Planificado
A11: tramo_precio | B11: UNIQUE | C11: (linea_granel_id, unidad_umbral, umbral) | D11: Sin tramos repetidos en una misma lista. | E11: Planificado
A12: pedido | B12: UNIQUE | C12: (tienda_id, numero) | D12: Número de pedido correlativo por tienda. | E12: Planificado
... A19: visita | B19: UNIQUE | C19: (tienda_id, inicio, posicion) | D19: Dos compradores no pueden tomar el mismo lugar en el mismo horario. | E19: Congelado
